Workbook

Sheet LISEZ-MOI
B1: StatApp 2026-2027 : sélection des sujets (KC)
B2: État du classeur
B3: Phases 1 et 2 réalisées : critères avec ancres (feuille « Critères »), identification des 83 sujets (« Identification »), scoring (« Scoring »), classement High / Mid / Ne pas toucher (« Classement »), règles (« Règles de classement ») et sources de la recherche web (« Sources web »). Tout est provisoire et à relire : les ancres et les critères n'ont pas encore été validés.
B4: Source : les 83 fiches PDF du dossier Docs/ (sujets n° 279 à 366 ; les numéros 283, 286, 287, 335 et 336 n'existent pas dans le dossier). Le lien « Ouvrir le PDF » est relatif à l'emplacement de ce classeur.
B5: Conventions de la feuille Identification
B6: Extraites telles quelles de la fiche : n°, organisme, titre, catégorie ENSAE, proposant, notation et commentaire ENSAE.
B7: Rédigées à la lecture de la fiche, sans jugement de valeur : type d'organisme, domaine réel, résumé, thèmes, méthodes, nature et statut des données, outils. Une information absente de la fiche est notée « non précisée » ou « à définir », jamais complétée par supposition.
B8: « Cohérence label ↔ contenu » : Oui, Partiel ou Non. Elle signale les sujets dont la catégorie ENSAE ne reflète pas bien le contenu. C'est un repérage, pas un score.
B9: « Type d'organisme » : déduit du nom et de la fiche ; les cas incertains sont marqués « à vérifier ». Les organismes CREST (toutes variantes de nom) sont regroupés pour le comptage.
B10: « Nb de fiches du même organisme » : valeur calculée une fois par script (non liée par formule).
B11: Notation ENSAE : à lire avec prudence
B12: Seules 20 fiches sur 83 portent une notation (8 « 3 », 7 « 2 », 5 « 1 »). L'absence de note n'est pas une mauvaise note : c'est une inconnue. Les agents d'analyse recevront cette information uniquement dans la lentille Note et faisabilité, pour ne pas biaiser les autres lentilles.
... B33: Les sujets 281, 282 et 361 (HSBC) se recoupent, comme 332, 333, 364 et 365 (Symbiotics) : il est inutile d'en demander plusieurs du même encadrant.

Sheet Critères
A1: Critères de scoring des sujets StatApp : version 2 (à valider)
A2: Échelle : 1 à 5 avec des ancres décrites par critère (rédigées, à relire). Pour « Valeur », 5 = excellent. Pour « Coût et risque », 5 = très coûteux ou risqué. Pas de pondération à ce stade. AJOUT = demandé lors de la dernière session.
A4: Code | B4: Famille | C4: Critère | D4: Ce que mesure le critère | E4: Sens | F4: Source d'information | G4: Lentille (agent) | H4: Statut vs v1 | I4: Ancre 1 | J4: Ancre 3 | K4: Ancre 5
A5: A1 | B5: A. Adéquation carrière | C5: Actuariat non-vie / ACAS | D5: GLM, fréquence-sévérité, tarification, provisionnement, théorie du risque (filière CAS) | E5: Valeur | F5: Fiche | G5: L1 Carrière | H5: v1 | I5: Aucun lien avec l'assurance non-vie ni la théorie du risque. | J5: Assurance non-vie en simple contexte, ou méthode de la filière (GLM, séries temporelles) appliquée hors assurance. | K5: Tarification, fréquence-sévérité, provisionnement ou théorie du risque non-vie au cœur du sujet, sur données d'assurance.
A6: A2 | B6: A. Adéquation carrière | C6: Réassurance / risque extrême / catastrophe | D6: Valeurs extrêmes, queues épaisses, copules, scénarios, climat et périls naturels, assurabilité | E6: Valeur | F6: Fiche | G6: L1 Carrière | H6: v1 | I6: Aucun lien avec les extrêmes, les périls naturels ou la réassurance. | J6: Risque climatique ou périls naturels abordés sans queues épaisses ni scénarios, ou méthodes d'extrêmes sur un objet non assurantiel. | K6: Valeurs extrêmes, copules, modélisation de catastrophes ou assurabilité du risque climatique au cœur du sujet.
A7: A3 | B7: A. Adéquation carrière | C7: Assurance vie / prévoyance (exploration) | D7: Mortalité, longévité, incapacité, ALM, Solvabilité II. Critère d'exploration : la filière ACAS n'est pas vie | E7: Valeur | F7: Fiche | G7: L1 Carrière | H7: AJOUT | I7: Aucun lien avec la mortalité, la longévité, l'incapacité ou l'ALM. | J7: Un volet vie ou prévoyance parmi d'autres (mortalité en variable annexe, ALM survolé). | K7: Mortalité, longévité, incapacité, ALM ou Solvabilité II vie au cœur du sujet. Critère d'exploration.
A8: A4 | B8: A. Adéquation carrière | C8: Quant finance (research / trading) | D8: Maths stochastiques, séries temporelles, dérivés, rigueur ; niveau mathématique lisible | E8: Valeur | F8: Fiche | G8: L1 Carrière | H8: v1 | I8: Aucun lien avec la finance de marché ; mathématiques élémentaires. | J8: Finance de marché (taux, actions, crédit) avec séries temporelles ou modèles classiques ; mathématiques peu visibles dans la fiche. | K8: Modèles stochastiques, dérivés, courbe de taux ou séries financières, avec un niveau mathématique clairement lisible dans la fiche.
A9: A5 | B9: A. Adéquation carrière | C9: Conseil généraliste (stratégie / risque) | D9: Cas business, restitution client, sectoriel (type Oliver Wyman, ICG) | E9: Valeur | F9: Fiche + web | G9: L1 Carrière | H9: v1 | I9: Sujet purement académique, sans client ni lecture business. | J9: Question métier réelle mais mono-sectorielle, ou restitution à un client seulement implicite. | K9: Cas business avec restitution à un client et décision à éclairer, dans l'esprit d'un cabinet de stratégie ou de risque.
A10: A6 | B10: A. Adéquation carrière | C10: Conseil spécialisé actuariat | D10: Missions actuarielles en cabinet : modèles, provisionnement, réglementaire, études pour assureurs et réassureurs | E10: Valeur | F10: Fiche + web | G10: L1 Carrière | H10: AJOUT | I10: Aucune mission de type actuariat en cabinet. | J10: Étude actuarielle ou réglementaire menée en interne chez un assureur ou une banque, ou cabinet sur un sujet non actuariel. | K10: Mission type d'un cabinet d'actuariat : modèle, provisionnement, réglementaire, étude pour assureurs ou réassureurs.
A11: A7 | B11: A. Adéquation carrière | C11: Institutions et développement | D11: Assurance paramétrique, pays émergents, secteur public, risque climatique souverain (type African Risk Capacity) | E11: Valeur | F11: Fiche + web | G11: L1 Carrière | H11: v1 | I11: Aucun lien avec le secteur public, les pays émergents ou l'assurance paramétrique. | J11: Institution publique ou question de développement, sans lien direct avec le risque ou l'assurance. | K11: Assurance paramétrique, risque climatique souverain, pays émergents ou institution internationale, avec lien direct au risque.
A12: A8 | B12: A. Adéquation carrière | C12: Compétences portables | D12: Compétences réutilisables dans plusieurs voies (R/Python, bayésien, survie, spatial, ML) | E12: Valeur | F12: Fiche | G12: L1 Carrière | H12: v1 | I12: Méthode ou outil de niche, difficilement réutilisable ailleurs. | J12: Deux ou trois compétences standard (Python, ML classique, séries temporelles), réutilisables mais génériques. | K12: Plusieurs compétences recherchées dans plusieurs voies (bayésien, survie, spatial, ML, R et Python) réellement pratiquées.
A13: A9 | B13: A. Adéquation carrière | C13: Motivation réelle | D13: Intérêt intrinsèque du sujet pour KC et le groupe sur quatre à cinq mois | E13: Valeur | F13: KC | G13: KC (humain) | H13: v1 | I13: Aucun intérêt ; sujet subi. Note donnée par KC, jamais par un agent. | J13: Intérêt correct, sans enthousiasme. | K13: Vrai intérêt personnel, tenable sur quatre à cinq mois pour KC et le groupe.
A14: B1 | B14: B. Signal marque et encadrant | C14: Notoriété de l'organisme | D14: Marque connue et influente, tous secteurs | E14: Valeur | F14: Web | G14: L2 Signal & exit | H14: v1 | I14: Organisme inconnu hors de son cercle. | J14: Connu dans son secteur ou en France. | K14: Marque connue et influente dans plusieurs secteurs, reconnue à l'international.
A15: B2 | B15: B. Signal marque et encadrant | C15: Pertinence de la marque pour nos cibles | D15: Poids de la marque auprès des réassureurs, cabinets, quant et institutions visés | E15: Valeur | F15: Web | G15: L2 Signal & exit | H15: v1 | I15: Marque sans poids auprès des réassureurs, cabinets, acteurs quant ou institutions visés. | J15: Marque connue d'une partie seulement des cibles. | K15: Marque qui compte directement auprès de plusieurs types de cibles (réassureurs, cabinets, quant, institutions).
... A40: F8 | B40: F. Coût et faisabilité | C40: Probabilité d'obtenir le sujet | D40: Demande attendue des autres élèves ; attribution par classement de 12 vœux | E40: Coût et risque | F40: Fiche + autres lentilles | G40: L4 Apprentissage & différenciation | H40: AJOUT | I40: Demande probablement faible : très bonnes chances de l'obtenir avec un bon rang de vœu. | J40: Demande moyenne. | K40: Très demandé (marque connue, sujet populaire, note 3) ; peu de chances même en vœu 1.
A42: Total : 36 critères (6 ajoutés).

Sheet Identification
A1: N° sujet | B1: Organisme | C1: Titre (fiche) | D1: Catégorie ENSAE (label officiel) | E1: Type d'organisme | F1: Proposant | G1: Langue | H1: Domaine réel (déduit du contenu) | I1: Résumé (en une à deux phrases) | J1: Thèmes / mots-clés | K1: Méthodes annoncées | L1: Nature des données | M1: Statut des données | N1: Outils cités | O1: Notation ENSAE (1-3) | P1: Commentaire ENSAE | Q1: Cohérence label ↔ contenu | R1: Note sur le label | S1: Nb de fiches du même organisme | T1: Fiche PDF
A2: 281 | B2: HSBC Global Asset Management | C2: Corrélation entre indices Action et Obligataire | D2: Actuariat | E2: Gestion d'actifs | F2: BRACH Loic | G2: FR | H2: Assurance vie — ALM / Solvabilité II | I2: Effet de Solvabilité II sur l'allocation d'actifs des assureurs vie européens (2014-2024, SFCR/EIOPA) + modèle ALM stylisé (SCR, ratio de solvabilité, volatilité du surplus) avec scénarios d'évolution du cadre. | J2: Solvabilité II, ALM, allocation stratégique, SCR, assureurs vie | K2: Formule standard Solvabilité II, optimisation de type Markowitz, simulation de scénarios | L2: Mixte | M2: Précisées (données de marché + SFCR/EIOPA publics) | O2: 2 | P2: C'est un sujet un peu avancé par rapport à la deuxième année de formation. Donc les élèves doivent en être conscients. | Q2: Partiel | R2: Le titre (corrélation actions/obligations) masque un sujet ALM / Solvabilité II pour assureurs vie | S2: 3 | T2: Ouvrir le PDF
A3: 285 | B3: SCOR | C3: Life and health insurance pricing with geographical data | D3: Actuariat | E3: Réassurance | F3: Luong Romain | G3: EN | H3: Assurance vie / prévoyance | I3: La localisation géographique améliore-t-elle la tarification du décès et de l'incapacité de travail ? Hypothèse : effet sur l'incapacité, pas sur la mortalité. | J3: Prévoyance, mortalité, incapacité, segmentation territoriale, tarification | K3: Logit, GLM, fréquence-sévérité, modèles de durée, random forests, DeepSurv | L3: Mixte | M3: Précisées (portefeuille(s) SCOR internes + open data externes) | N3: R, Python | O3: 3 | P3: Sujet intéressant, en parfaite adéquation avec les enseignements de 2A. | Q3: Oui | S3: 1 | T3: Ouvrir le PDF
A4: 292 | B4: CREST ENSAE | C4: Semantic Credit Risk Pricing with Large Language Models | D4: Actuariat | E4: Recherche académique | F4: NIAKH Fallou | G4: FR | H4: Risque de crédit (ML) | I4: Scoring de crédit par embeddings sémantiques de LLM (prompt → embedding → ACP → régression logistique), transposé de travaux récents sur la tarification en assurance. | J4: Scoring de crédit, LLM, embeddings, attributs protégés | K4: Régression logistique, XGBoost/LightGBM, embeddings LLM, ACP, fine-tuning contrastif | L4: Publiques | M4: Précisées (German Credit Data, 1 000 obs.) | Q4: Partiel | R4: Classé Actuariat ; objet = risque de crédit ; méthode importée de la tarification assurance | S4: 19 | T4: Ouvrir le PDF
A5: 309 | B5: Ekimetrics | C5: Apprentissage de lois a priori par transfert entre portefeuilles : une approche de meta-learning bayésien | D5: Actuariat | E5: Conseil / data science | F5: HU François | G5: FR | H5: Statistique bayésienne — crédibilité actuarielle | I5: Transfert de lois a priori entre portefeuilles par meta-learning bayésien ; deux terrains simulés : mesure d'efficacité marketing et portefeuilles d'assurance non-vie (GLM Poisson hiérarchique, comparaison à Bühlmann-Straub). | J5: Théorie de la crédibilité, bayésien hiérarchique, meta-learning, tarification non-vie | K5: GLM Poisson hiérarchique, régression bayésienne hiérarchique, NUTS/PyMC, estimateur de Bühlmann-Straub | L5: Simulées | M5: Précisées (générateur fourni par l'encadrant ; validation sur données réelles optionnelle) | N5: Python (PyMC) | Q5: Oui | R5: Contenu actuariel réel (crédibilité, comptage non-vie) sous un habillage méthodologique | S5: 6 | T5: Ouvrir le PDF
A6: 347 | B6: BNP Paribas Cardif | C6: Implémentation d'un outil de veille réglementaire assisté par l'intelligence artificielle en assurance | D6: Actuariat | E6: Assurance | F6: TOUKAM Eugénie Rinelle | G6: FR | H6: Assurance — réglementaire / NLP | I6: Outil de veille réglementaire (EIOPA, ACPR, Commission européenne) assisté par LLM / RAG pour un assureur. | J6: Solvabilité II, réglementation assurance, NLP, RAG | K6: NLP, LLM, RAG | L6: Publiques | M6: Précisées (textes réglementaires publics) | O6: 2 | P6: Le sujet me semble peu technique et donc il y a un risque élevé de contenu scientifique limité. Il faudra donc bien faire attention à ce point. | Q6: Partiel | R6: Contexte assurance mais contenu NLP/LLM ; pas de modélisation actuarielle | S6: 1 | T6: Ouvrir le PDF
A7: 348 | B7: KORFED SAS | C7: Modélisation et prédiction du risque auto : comparaison des méthodes actuarielles, du Machine Learning et de l'Intelligence Artificielle générative | D7: Actuariat | E7: Non précisé dans la fiche | F7: KORFED Marouan | G7: FR | H7: Assurance non-vie (auto) | I7: Comparer plusieurs générations de modèles de risque auto : GLM actuariels (fréquence et coût), ML (boosting, réseaux de neurones) et IA générative ; arbitrage performance / interprétabilité. | J7: Tarification auto, fréquence-sévérité, interprétabilité, ML vs GLM | K7: GLM (Poisson, binomiale négative, Gamma, log-normale), RF, boosting, réseaux de neurones, IA générative, explicabilité | L7: Internes (fournies) | M7: Partielles (contrats et sinistres auto anonymisés ; disponibilité non confirmée, cf. commentaire ENSAE) | O7: 3 | P7: Le sujet est adéquat aux attendus du Statapp. Je n'ai pas vu d'infos sur la disponibilité des données. | Q7: Oui | S7: 1 | T7: Ouvrir le PDF
A8: 280 | B8: HeadMind Partners | C8: Visual Search – Classification d'image | D8: Autre | E8: Conseil / ESN | F8: DEFOSSEZ Lucie | G8: FR | H8: ML — vision par ordinateur | I8: Pipeline de recherche visuelle pour l'e-commerce mode : classifier les vêtements portés sur une photo et retrouver l'article du catalogue. | J8: Vision par ordinateur, classification d'images | K8: Vision par ordinateur moderne (voir fiche) | L8: Non précisées | M8: Non précisées (la section Données décrit des objectifs) | O8: 1 | P8: Sujet hors scope ENSAE, nous ne faisons pas de détection d'image ni de fine tuning de modèles. | Q8: Oui | S8: 2 | T8: Ouvrir le PDF
A9: 288 | B9: Société Générale | C9: L'incertitude des systèmes multi-agents | D9: Autre | E9: Banque | F9: VIGNARD Alexis | G9: FR | H9: ML — LLM multi-agents | I9: Quantifier l'incertitude des systèmes multi-agents fondés sur des LLM (LangGraph, benchmarks d'agents). | J9: LLM, agents, incertitude, benchmarks | K9: Agents LangGraph, modèles open source pré-entraînés | L9: Publiques | M9: Partielles (environnement d'évaluation à identifier et à déployer) | N9: LangGraph | O9: 2 | P9: Sujet intéressant mais très déconseillé: le gros du travail nécessite une compréhension et une maîtrise de ce qu'est un LLM (programme de fin de 3A) et utilise assez peu la formation ENSAE 1A-2A. Le sujet semble être un programme de recherche de thèse, pas un stat-app. | Q9: Oui | S9: 2 | T9: Ouvrir le PDF
A10: 314 | B10: Ekimetrics | C10: Why Is the Model Uncertain? Explaining and Reducing Predictive Uncertainty in Machine Learning | D10: Autre | E10: Conseil / data science | F10: AGNIMO Yedidia | G10: EN | H10: ML — incertitude prédictive | I10: Expliquer pourquoi un modèle ML est incertain pour une observation donnée (au-delà de l'intervalle de prédiction) ; application aux ventes immobilières d'Ames. | J10: Quantification d'incertitude, conformal prediction, SHAP, régression quantile | K10: Régression linéaire, arbres, régression quantile, conformal prediction, SHAP | L10: Publiques | M10: Précisées (Ames Housing, 2 930 ventes) | Q10: Oui | R10: Pas de lien métier assurance/finance dans la fiche | S10: 6 | T10: Ouvrir le PDF
A11: 291 | B11: RTE | C11: Analyse longitudinale de la base OPERAT - Comment les consommations énergétiques des établissements tertiaires français ont-elles évolué entre 2020 et 2024, et quels facteurs expliquent l'hétérogénéité des trajectoires ? | D11: Environnement Energie et Mobilité | E11: Industrie / énergie | F11: Crocombette Christophe | G11: FR | H11: Énergie — consommation tertiaire | I11: Évolution 2020-2024 de l'intensité énergétique d'environ 250 000 établissements tertiaires (base OPERAT) et facteurs d'hétérogénéité. | J11: Efficacité énergétique, hétérogénéité, longitudinal | K11: Régression, clustering, logit | L11: Internes (fournies) | M11: Précisées (~1 M d'entrées, base OPERAT) | Q11: Oui | S11: 1 | T11: Ouvrir le PDF
A12: 304 | B12: GazTransport et Technigaz | C12: Identification des anomalies de trajectoires de méthaniers pour l'obtention de statistiques agrégées sur les temps d'attente permettant de quantifier les gains d'une approche « Just-in-time » | D12: Environnement Energie et Mobilité | E12: Industrie / maritime-GNL | F12: Montiel Antoine | G12: FR | H12: Transport / logistique | I12: Détecter les temps d'attente anormaux des méthaniers à partir des trajectoires AIS (~900 navires) et chiffrer les gains d'une approche « just-in-time ». | J12: AIS, détection d'anomalies, séries temporelles de position | K12: Indicateurs de trajectoire, probabilités conditionnelles, modèles supervisés | L12: Internes (fournies) | M12: Précisées (AIS, navires, armateurs, terminaux) | Q12: Oui | S12: 1 | T12: Ouvrir le PDF
A13: 305 | B13: CREST | C13: Disaster Risk Reduction and Climate Change Adaptation in European Metropolises | D13: Environnement Energie et Mobilité | E13: Recherche académique | F13: Rufat Samuel | G13: EN | H13: Risque de catastrophe / adaptation climatique | I13: Comportements d'adaptation aux inondations et canicules dans les grandes métropoles européennes (projet ERC FiBeGa) : prédicteurs locaux et simulation spatialement explicite. | J13: Catastrophes naturelles, adaptation, perception du risque, spatial, ABM | K13: Analyse de données R/Python, modélisation multi-agents (ABM, apprentissage possible) | L13: Mixte | M13: Précisées (enquêtes n=5 000, recensement carroyé, hospitalisations, climat/catastrophes) | N13: R, Python | Q13: Partiel | R13: Classé Environnement ; sujet de risque de catastrophe naturelle | S13: 19 | T13: Ouvrir le PDF
A14: 339 | B14: INRAE | C14: Les arbitrages spatiaux des ménages : coûts du logement, coûts de mobilité et contraintes temporelles | D14: Environnement Energie et Mobilité | E14: Recherche académique | F14: BOUSCASSE HELENE | G14: FR | H14: Économie des ménages (logement / mobilité) | I14: Arbitrage coût du logement / coût et temps de transport : appariement statistique Budget de famille × Emploi du temps, puis coût résidentiel généralisé. | J14: Mobilité, logement, valeur du temps, appariement statistique | K14: Régression bêta / logit fractionnaire, modèles à zéros, régression quantile, hot-deck / PMM, imputation multiple | L14: Publiques | M14: Précisées (Budget de famille 2011/2017, Emploi du temps) | Q14: Oui | S14: 2 | T14: Ouvrir le PDF
A15: 342 | B15: CREST | C15: Quel prix pour l'eau potable – Demande, hétérogénéité et ciblage des subventions en Inde rurale | D15: Environnement Energie et Mobilité | E15: Recherche académique | F15: Crepon Bruno | G15: FR | H15: Économie du développement | I15: Demande d'eau potable livrée à domicile et ciblage des subventions, à partir d'une expérience randomisée (Inde rurale, ~60 000 ménages). | J15: Évaluation d'impact, demande, élasticité-prix, WTP/WTA, ciblage | K15: Effets de traitement, estimation de demande, panel à effets fixes, hétérogénéité | L15: Internes (fournies) | M15: Précisées (expérience randomisée, Odisha) | Q15: Oui | S15: 19 | T15: Ouvrir le PDF
A16: 344 | B16: INRAE | C16: Homo economicus prend-il le volant – Rationalité limitée et coûts de mobilité | D16: Environnement Energie et Mobilité | E16: Recherche académique | F16: BOUSCASSE HELENE | G16: FR | H16: Économie comportementale (mobilité) | I16: Les ménages connaissent-ils le coût de leur voiture ? Rationalité limitée, postes oubliés, préférence pour le présent. | J16: Économie comportementale, coût de la voiture, biais de perception | K16: Statistique descriptive, régression, modèles à variable dépendante qualitative, maximum de vraisemblance (option) | L16: Enquête | M16: Précisées (enquête LocarEsid 2023-2024) | Q16: Oui | S16: 2 | T16: Ouvrir le PDF
A17: 351 | B17: ENPC | C17: Mesurer l'économie productive dans les quartiers de gare du Grand Paris Express | D17: Environnement Energie et Mobilité | E17: Recherche académique | F17: Crague Gilles | G17: FR | H17: Économie urbaine | I17: Mesurer l'économie productive autour des 68 gares du Grand Paris Express (rayon 800 m) à partir de données ouvertes. | J17: Économie urbaine, établissements, géolocalisation, observatoire | K17: Méthodes ouvertes (au choix des élèves) | L17: Publiques | M17: Précisées (Sirene géolocalisée et autres open data) | Q17: Oui | S17: 1 | T17: Ouvrir le PDF
A18: 353 | B18: CREST | C18: When a critical material becomes scarce, do firms dig in and innovate around it, or pivot into new activities? And does their existing technological know-how pull them toward the same constrained input? | D18: Environnement Energie et Mobilité | E18: Recherche académique | F18: Zerbib Olivier David | G18: EN | H18: Économie industrielle / innovation | I18: Face à la raréfaction d'un matériau critique, les firmes innovent-elles ou se redéploient-elles ? | J18: Matériaux critiques, innovation, brevets, chocs d'offre | K18: Event study, différences-de-différences | L18: Internes (fournies) | M18: Précisées (dépendance aux matériaux, ruptures, portefeuilles produits/brevets ; mise en forme à prévoir) | Q18: Oui | S18: 19 | T18: Ouvrir le PDF
A19: 360 | B19: EDF R&D | C19: Méthodes statistiques pour la prévision de production renouvelable | D19: Environnement Energie et Mobilité | E19: Industrie / énergie | F19: Upton Henri | G19: FR | H19: Énergie — prévision renouvelable | I19: Prévision de la production éolienne nationale à partir de prévisions météo (données de type compétition Codabench). | J19: Éolien, prévision, météo | K19: Deep learning, modèles de fondation, boosting, random forest | L19: Publiques | M19: Précisées (page de compétition privée, déjà disponible) | Q19: Oui | R19: Fiche très courte | S19: 1 | T19: Ouvrir le PDF
A20: 362 | B20: CANOPY ENERGIES | C20: Peut-on prédire la croissance du Pongamia à partir du sol – Modélisation statistique et spatiale d'une plantation agroforestière à Madagascar | D20: Environnement Energie et Mobilité | E20: Environnement / projet de restauration | F20: GARCHERY Guillaume | G20: FR | H20: Environnement — agronomie / spatial | I20: Prédire survie et croissance du Pongamia à Madagascar (projet Fagnako) à partir du sol, de l'âge, de la topographie ; modélisation longitudinale et spatiale. | J20: Agroforesterie, statistique spatiale, croissance, survie | K20: GAM, effets mixtes, modèles de survie, statistique spatiale, RF/boosting, validation croisée spatiale | L20: Internes (fournies) | M20: Précisées (campagnes d'inventaire du projet) | Q20: Oui | S20: 1 | T20: Ouvrir le PDF
A21: 282 | B21: HSBC Global Asset Management | C21: Stratégies optionnelles de protection pour investisseurs de long terme | D21: Finance | E21: Gestion d'actifs | F21: BRACH Loic | G21: FR | H21: Gestion d'actifs / produits structurés | I21: Stratégies optionnelles de protection (puts, collars, CPPI/OBPI, volatilité cible) pour investisseurs de long terme ; efficacité selon le régime de marché. | J21: Protection de portefeuille, options, CPPI, backtesting | K21: Pricing et simulation stochastique, backtesting de stratégies | L21: Marché | M21: Précisées (historiques de prix d'indices actions et obligataires) | O21: 3 | P21: Le sujet est bien adéquat au contenu des enseignements de deuxième année. Il y a des composantes techniques mais aussi opérationnelles. | Q21: Oui | S21: 3 | T21: Ouvrir le PDF
A22: 296 | B22: Partners Group | C22: Mandates representation and optimization via cross trades | D22: Finance | E22: Gestion d'actifs | F22: Memmi Pierre | G22: EN | H22: Gestion d'actifs — private markets | I22: Représentation de portefeuilles d'investisseurs et optimisation par échanges d'actifs (cross trades). | J22: Portefeuilles, similarité, cross trades | K22: À confirmer (TBC) | L22: Internes (fournies) | M22: Partielles (variables listées ; objectifs et modèles à confirmer, cf. commentaire ENSAE) | O22: 2 | P22: Il n'y a pas suffisamment d'informations sur le sujet, notamment sur les objectifs de l'étude, la disponibilité des données et, surtout, les méthodes qui seront utilisées durant le projet. | Q22: Oui | S22: 1 | T22: Ouvrir le PDF
A23: 324 | B23: Banque de France | C23: Modélisation du risque de crédit en intégrant les engagements hors bilan | D23: Finance | E23: Institution publique | F23: BOUFFIN Joshua | G23: FR | H23: Risque de crédit | I23: Intégrer les engagements hors bilan (cas des hyperscalers) dans les modèles de risque de crédit (Merton/KMV, Altman Z). | J23: Risque de crédit, hors bilan, modèles structurels, hyperscalers | K23: Merton / KMV, Altman Z-score | L23: Marché | M23: Précisées (Bloomberg, marchés européens et américains) | O23: 3 | P23: Je trouve que le sujet est adéquat et la démarche attendue est bien explicitée. | Q23: Oui | S23: 2 | T23: Ouvrir le PDF
A24: 332 | B24: Symbiotics Asset Management | C24: Constructing Yield Curves in Illiquid Emerging Market | D24: Finance | E24: Gestion d'actifs | F24: Belpaire Michael | G24: EN | H24: Marchés de taux / dérivés | I24: Construire des courbes de taux sur marchés émergents illiquides (réplication de Khakimzhanov et al., 2019 : Nelson-Siegel sur données éparses). | J24: Courbe des taux, illiquidité, Nelson-Siegel | K24: Nelson-Siegel adapté aux transactions éparses | L24: Publiques | M24: Partielles (sources potentielles : banques centrales, bourses, ministères) | O24: 3 | P24: Sujet adéquat | Q24: Oui | S24: 4 | T24: Ouvrir le PDF
A25: 333 | B25: Symbiotics Asset Management | C25: Simplifying Corporate Default Risk Prediction Using Public Financial Data | D25: Finance | E25: Gestion d'actifs | F25: Belpaire Michael | G25: EN | H25: Risque de crédit | I25: Prédire la défaillance d'entreprises cotées avec peu d'indicateurs publics et interprétables ; comparaison à Altman/Ohlson, hazard et ML. | J25: Défaut d'entreprise, parcimonie, interprétabilité | K25: Ratios (Altman, Ohlson), logit / hazard (Shumway, Campbell et al.), benchmark ML | L25: Publiques | M25: Précisées (SEC EDGAR) | O25: 3 | P25: Sujet adéquat | Q25: Oui | S25: 4 | T25: Ouvrir le PDF
A26: 338 | B26: Société Générale | C26: Explaining Cheapest-to-Deliver (CTD) Bond Transitions in Government Bond Futures | D26: Finance | E26: Banque | F26: Draghia Denisa | G26: EN | H26: Marchés de taux / dérivés | I26: Expliquer et prévoir les changements de Cheapest-to-Deliver dans les futures obligataires souverains. | J26: Futures obligataires, CTD, courbe des taux | K26: Régression, random forest, XGBoost, modèle stochastique | L26: Marché | M26: Précisées (données de marché du future) | O26: 3 | P26: Ok même si je ne suis pas expert du sujet. | Q26: Oui | S26: 2 | T26: Ouvrir le PDF
A27: 355 | B27: Ornikar Assurance | C27: Mesure de l'assurabilité en assurance Auto | D27: Finance | E27: Assurance | F27: GORGE Guillaume | G27: FR | H27: Assurance non-vie (auto) — assurabilité | I27: Mesurer la « frontière de l'assurabilité » en auto (prix, exclusions, nombre d'assureurs répondant) à partir de demandes de cotation. | J27: Assurabilité, climat, prix, exclusions | K27: Autoencodeur, réseaux de neurones, XGBoost, classification | L27: Internes (fournies) | M27: Précisées (demandes de cotation du marché) | Q27: Partiel | R27: Classé Finance ; contenu = assurance non-vie | S27: 1 | T27: Ouvrir le PDF
A28: 356 | B28: VIA AM | C28: Finding Factors Using NLP/LLMs on 10-K/10-Q/8-K Filings | D28: Finance | E28: Gestion d'actifs | F28: Molinaro Matéo | G28: EN | H28: Finance quantitative — NLP | I28: Extraire des facteurs du texte des filings SEC (10-K/10-Q/8-K) par NLP/LLM et tester leur apport face aux facteurs classiques. | J28: Facteurs, filings SEC, NLP, asset pricing | K28: TF-IDF, embeddings, FinBERT / LLM, lasso/ridge/elastic net, LightGBM/XGBoost, régression | L28: Publiques | M28: Précisées (SEC EDGAR, Open Source Asset Pricing) | Q28: Oui | S28: 1 | T28: Ouvrir le PDF
A29: 361 | B29: HSBC Global Asset Management | C29: Gestion d'actif – Conception de portefeuilles optionnels protégés sous contrainte Solvabilité II | D29: Finance | E29: Gestion d'actifs | F29: BRACH Loic | G29: FR | H29: Gestion d'actifs / Solvabilité II (assureurs vie) | I29: Concevoir des portefeuilles optionnels protégés pour assureurs vie et fonds de retraite sous contrainte de capital Solvabilité II. | J29: Solvabilité II, options, CPPI/OBPI, assureurs vie | K29: Simulation de marché (diffusion géométrique, volatilité stochastique, bootstrap), calibration | L29: Marché | M29: Précisées (historiques de prix d'indices) | Q29: Partiel | R29: Classé Finance ; contrainte réglementaire d'assurance vie centrale | S29: 3 | T29: Ouvrir le PDF
A30: 364 | B30: Symbiotics Asset Management | C30: Statistical Modelling, Stress Testing and Optimal Structuring of a Blended Finance Fund | D30: Finance | E30: Gestion d'actifs | F30: Belpaire Michael | G30: EN | H30: Finance de développement — structuration | I30: Modélisation statistique, stress tests et structuration optimale (tranches junior / senior) d'un fonds de blended finance. | J30: Blended finance, tranche first-loss, stress test, structuration | K30: À définir | L30: À définir | M30: À définir (données et modèles « to be defined ») | Q30: Oui | R30: Cœur du sujet = structuration en tranches de pertes (first-loss) et stress tests | S30: 4 | T30: Ouvrir le PDF
A31: 365 | B31: Symbiotics Asset Management | C31: Modélisation factorielle et stratégie de couverture d'un portefeuille marchés émergents | D31: Finance | E31: Gestion d'actifs | F31: Belpaire Michael | G31: FR | H31: Marchés émergents — devises | I31: Modèle factoriel (ACP) des devises émergentes et frontières, déterminants, portage, puis stratégie de couverture backtestée. | J31: Devises émergentes, ACP, portage, couverture | K31: ACP, économétrie, backtest | L31: Internes (fournies) | M31: Précisées (données financières fournies par l'entreprise) | N31: R | Q31: Oui | S31: 4 | T31: Ouvrir le PDF
A32: 366 | B32: BPCE SA | C32: Estimation des pertes extrêmes en risque de crédit | D32: Finance | E32: Banque | F32: SICAN Silas | G32: FR | H32: Risque de crédit — dépendance extrême | I32: VaR 99,9 % d'un portefeuille de crédit multivarié avec copules (Gaussienne, Student, archimédiennes) pour capter la dépendance de queue. | J32: Copules, dépendance de queue, VaR, capital économique | K32: Copules, séries temporelles des marges, économétrie | L32: Internes (fournies) | M32: Partielles (séries multivariées de taux de défaut et pertes attendues ; origine à confirmer) | Q32: Oui | R32: Classé Finance ; cœur du sujet = risque extrême / dépendance de queue | S32: 1 | T32: Ouvrir le PDF
A33: 289 | B33: DG Trésor | C33: Analyse sectorielle des fluctuations du prix du pétrole | D33: Macroeconomie | E33: Institution publique | F33: LEE Raphael | G33: FR | H33: Macroéconomie — pétrole | I33: Effets sectoriels des chocs de prix du pétrole sur l'activité (guerre en Ukraine, Moyen-Orient). | J33: Prix du pétrole, chocs, VAR sectoriel | K33: VAR, caractérisation statistique des séries | L33: Publiques | M33: Précisées (OCDE, FMI) | Q33: Oui | S33: 2 | T33: Ouvrir le PDF
A34: 290 | B34: DG Trésor | C34: L'impact économique du vieillissement | D34: Macroeconomie | E34: Institution publique | F34: LEE Raphaël | G34: FR | H34: Macroéconomie — démographie | I34: Effets du vieillissement sur la consommation et la croissance du PIB. | J34: Vieillissement, consommation, croissance | K34: Non précisées (analyse puis estimation des effets sur données macro) | L34: Publiques | M34: Précisées (OCDE, FMI) | Q34: Oui | S34: 2 | T34: Ouvrir le PDF
A35: 293 | B35: QuantCube Technology | C35: Nowcasting hiérarchique de la consommation des ménages en Espagne | D35: Macroeconomie | E35: Data / fintech | F35: de Roux Nicolas de Roux | G35: FR | H35: Macroéconomie — nowcasting | I35: Nowcasting hiérarchique de la consommation des ménages espagnols (agrégat trimestriel et postes de dépense) avec cohérence comptable. | J35: Nowcasting, prévision hiérarchique, réconciliation | K35: Lasso/Ridge, SARIMA, VAR, facteurs dynamiques à fréquence mixte, forêts aléatoires | L35: Mixte | M35: Précisées (INE, Banco de España, Eurostat + données alternatives) | Q35: Oui | S35: 2 | T35: Ouvrir le PDF
A36: 295 | B36: QuantCube Technology | C36: Nowcasting des Nonfarm Payrolls américains à partir de données alternatives haute fréquence | D36: Macroeconomie | E36: Data / fintech | F36: MEREAU Julien | G36: FR | H36: Macroéconomie — nowcasting | I36: Nowcasting des Nonfarm Payrolls américains avec des données alternatives haute fréquence. | J36: Nowcasting, emploi, données alternatives, fréquences mixtes | K36: SARIMAX, VAR, modèles à facteurs dynamiques, modèles espace-état | L36: Mixte | M36: Précisées (BLS, jobless claims, JOLTS + données alternatives) | Q36: Oui | S36: 2 | T36: Ouvrir le PDF
A37: 300 | B37: European University Institute | C37: The Effects of Geopolitical Risk on Innovation: Evidence from International Patent Data | D37: Macroeconomie | E37: Recherche académique | F37: Lomo Pedro | G37: EN | H37: Macroéconomie — innovation | I37: Effets du risque géopolitique sur l'innovation internationale à partir des brevets OCDE. | J37: Risque géopolitique, brevets, flux de connaissances | K37: Économétrie de panel (effets fixes) | L37: Publiques | M37: Précisées (brevets et citations OCDE, mesures de risque géopolitique) | Q37: Oui | S37: 1 | T37: Ouvrir le PDF
A38: 326 | B38: Banque de France | C38: Un modèle de gravité pour expliquer les flux touristiques entrants en France par nationalité | D38: Macroeconomie | E38: Institution publique | F38: Pradelle Félix | G38: FR | H38: Macroéconomie — commerce / tourisme | I38: Modèle de gravité des flux de voyageurs entrants en France par nationalité (2022-2025). | J38: Gravité, tourisme, balance des paiements | K38: MCO à effets fixes, PPML, LASSO (option) | L38: Internes (fournies) | M38: Précisées (séries mensuelles agrégées et légèrement bruitées) | Q38: Oui | S38: 2 | T38: Ouvrir le PDF
A39: 354 | B39: Lazard Frères | C39: Dynamique de la dette française | D39: Macroeconomie | E39: Banque d'affaires / conseil | F39: Quisefit Antonin | G39: FR | H39: Macro-finance — dette souveraine | I39: Dette française : déterminants du spread OAT-Bund (macro, risque global, politique) et signaux avant-coureurs de changement de régime (early warning, équilibres multiples). | J39: Spread souverain, event study, early warning, changement de régime | K39: Régression sur séries temporelles, event study, Markov-switching, probit/logit | L39: Marché | M39: Précisées (Bloomberg/Refinitiv ou séries publiques BCE, BdF, Eurostat) | Q39: Oui | S39: 1 | T39: Ouvrir le PDF
A40: 301 | B40: Withings SAS | C40: Souscription et résiliation d'un abonnement de santé connectée : détecter les signaux d'usage précurseurs et identifier les leviers d'action | D40: Marketing Quantitatif | E40: Entreprise (santé connectée) | F40: CARRIE Hugo | G40: FR | H40: Marketing / data business — survie et rétention | I40: Détecter les signaux d'usage qui précèdent la souscription et la résiliation d'un abonnement santé connectée, puis ceux sur lesquels l'entreprise peut agir. | J40: Rétention, churn, modèle de durée, prédiction vs effet d'une intervention | K40: Courbes de rétention, modèle de Cox ou à temps discret, prédiction, volet décisionnel (effet d'une intervention) | L40: Internes (fournies) | M40: Précisées (extraction pseudonymisée, plusieurs centaines de milliers d'utilisateurs, 24-36 mois) | Q40: Oui | S40: 1 | T40: Ouvrir le PDF
...

Sheet Scoring
A1: Scoring des 83 sujets StatApp : version provisoire (à relire)
A2: Échelle 1 à 5 selon les ancres de la feuille « Critères ». Pour « Coût et risque », 5 = très coûteux ou risqué. Cellules jaunes : à renseigner par KC (A9, F4). D1 en gris italique : sujet non noté par l'ENSAE, valeur 3 par défaut (inconnue, non pénalisée). Colonnes marquées (web) : issues de la recherche web, voir la feuille « Sources web ». Familles et indice calculés par formule : modifier un score les met à jour.
E3: A. Adéquation carrière | N3: B. Signal marque et encadrant | S3: C. Exit | W3: D. Note | AC3: E. Apprentissage et différenciation | AG3: F. Coût et faisabilité | AO3: Familles et indice (formules)
A4: N° sujet | B4: Organisme | C4: Titre (fiche) | D4: Catégorie ENSAE | E4: A1 Actuariat non-vie / ACAS | F4: A2 Réassurance / risque extrême / catastrophe | G4: A3 Assurance vie / prévoyance (exploration) | H4: A4 Quant finance (research / trading) | I4: A5 Conseil généraliste (stratégie / risque) | J4: A6 Conseil spécialisé actuariat | K4: A7 Institutions et développement | L4: A8 Compétences portables | M4: A9 Motivation réelle [KC] | N4: B1 Notoriété de l'organisme (web) | O4: B2 Pertinence de la marque pour nos cibles (web) | P4: B3 Réputation de l'encadrant (web) | Q4: B4 Lisibilité en une ligne | R4: B5 Signal académique | S4: C1 Probabilité de débouché (web) | T4: C2 Recommandation et réseau (web) | U4: C3 Portée internationale (web) | V4: C4 Valeur en entretien | W4: D1 Notation et commentaire ENSAE | X4: D2 Clarté du cahier des charges | Y4: D3 Données : disponibilité et accès | Z4: D4 Adéquation au programme de 2A | AA4: D5 Calibrage scientifique | AB4: D6 Qualité probable de l'encadrement (web) | AC4: E1 Profondeur mathématique et statistique | AD4: E2 Nouveauté des méthodes acquises | AE4: E3 Livrable montrable | AF4: E4 Différenciation | AG4: F1 Budget de temps réaliste | AH4: F2 Difficulté technique | AI4: F3 Charge de préparation des données | AJ4: F4 Compatibilité avec le calendrier [KC] | AK4: F5 Risque d'exécution | AL4: F6 Répartissabilité à 4-5 | AM4: F7 Confidentialité | AN4: F8 Probabilité d'obtenir le sujet | AO4: Fit (max A1-A7) | AP4: Signal (moy. B1-B5) | AQ4: Exit (moy. C1-C4) | AR4: Note (moy. D1, D2, D4, D6) | AS4: Apprentissage (moy. E1-E4) | AT4: Risque (moy. D3, D5, F1-F7) | AU4: Indice (moyenne des six familles) | AV4: Confiance (fiche) | AW4: Confiance (web) | AX4: Note ENSAE | AY4: Ajustements après lecture du commentaire ENSAE
A5: 279 | B5: HeadMind Partners | C5: Newsletter AI | D5: NLP | E5: 1 | F5: 1 | G5: 1 | H5: 1 | I5: 1 | J5: 1 | K5: 1 | L5: 2 | N5: 2 | O5: 1 | P5: 3 | Q5: 3 | R5: 1 | S5: 2 | T5: 2 | U5: 2 | V5: 2 | W5: 1 | X5: 4 | Y5: 2 | Z5: 1 | AA5: 5 | AB5: 3 | AC5: 1 | AD5: 2 | AE5: 4 | AF5: 3 | AG5: 4 | AH5: 2 | AI5: 3 | AK5: 3 | AL5: 3 | AM5: 1 | AN5: 2 | AO5: =MAX(E5:K5) -> 1 | AP5: =AVERAGE(N5:R5) -> 2 | AQ5: =AVERAGE(S5:V5) -> 2 | AR5: =AVERAGE(W5,X5,Z5,AB5) -> 2.25 | AS5: =AVERAGE(AC5:AF5) -> 2.5 | AT5: =AVERAGE(Y5,AA5,AG5:AM5) -> 2.875 | AU5: =(AO5+AP5+AQ5+AR5+AS5+(6-AT5))/6 -> 2.1458333 | AV5: Haute | AW5: Faible | AX5: 1
A6: 280 | B6: HeadMind Partners | C6: Visual Search – Classification d'image | D6: Autre | E6: 1 | F6: 1 | G6: 1 | H6: 1 | I6: 2 | J6: 1 | K6: 1 | L6: 3 | N6: 2 | O6: 1 | P6: 3 | Q6: 3 | R6: 1 | S6: 2 | T6: 2 | U6: 2 | V6: 2 | W6: 1 | X6: 4 | Y6: 3 | Z6: 1 | AA6: 5 | AB6: 3 | AC6: 1 | AD6: 4 | AE6: 4 | AF6: 3 | AG6: 4 | AH6: 4 | AI6: 3 | AK6: 4 | AL6: 3 | AM6: 1 | AN6: 2 | AO6: =MAX(E6:K6) -> 2 | AP6: =AVERAGE(N6:R6) -> 2 | AQ6: =AVERAGE(S6:V6) -> 2 | AR6: =AVERAGE(W6,X6,Z6,AB6) -> 2.25 | AS6: =AVERAGE(AC6:AF6) -> 3 | AT6: =AVERAGE(Y6,AA6,AG6:AM6) -> 3.375 | AU6: =(AO6+AP6+AQ6+AR6+AS6+(6-AT6))/6 -> 2.3125 | AV6: Haute | AW6: Faible | AX6: 1 | AY6: D5 4→5
A7: 281 | B7: HSBC Global Asset Management | C7: Corrélation entre indices Action et Obligataire | D7: Actuariat | E7: 1 | F7: 1 | G7: 5 | H7: 3 | I7: 2 | J7: 4 | K7: 1 | L7: 3 | N7: 5 | O7: 3 | P7: 3 | Q7: 2 | R7: 2 | S7: 3 | T7: 3 | U7: 4 | V7: 4 | W7: 2 | X7: 4 | Y7: 2 | Z7: 2 | AA7: 4 | AB7: 3 | AC7: 3 | AD7: 3 | AE7: 4 | AF7: 4 | AG7: 4 | AH7: 3 | AI7: 4 | AK7: 3 | AL7: 2 | AM7: 1 | AN7: 2 | AO7: =MAX(E7:K7) -> 5 | AP7: =AVERAGE(N7:R7) -> 3 | AQ7: =AVERAGE(S7:V7) -> 3.5 | AR7: =AVERAGE(W7,X7,Z7,AB7) -> 2.75 | AS7: =AVERAGE(AC7:AF7) -> 3.5 | AT7: =AVERAGE(Y7,AA7,AG7:AM7) -> 2.875 | AU7: =(AO7+AP7+AQ7+AR7+AS7+(6-AT7))/6 -> 3.4791667 | AV7: Haute | AW7: Faible | AX7: 2 | AY7: D4 3→2, D5 3→4
A8: 282 | B8: HSBC Global Asset Management | C8: Stratégies optionnelles de protection pour investisseurs de long terme | D8: Finance | E8: 1 | F8: 1 | G8: 3 | H8: 5 | I8: 2 | J8: 2 | K8: 1 | L8: 3 | N8: 5 | O8: 3 | P8: 3 | Q8: 4 | R8: 3 | S8: 3 | T8: 3 | U8: 4 | V8: 4 | W8: 3 | X8: 4 | Y8: 2 | Z8: 5 | AA8: 3 | AB8: 3 | AC8: 4 | AD8: 3 | AE8: 4 | AF8: 3 | AG8: 3 | AH8: 3 | AI8: 2 | AK8: 2 | AL8: 2 | AM8: 1 | AN8: 3 | AO8: =MAX(E8:K8) -> 5 | AP8: =AVERAGE(N8:R8) -> 3.6 | AQ8: =AVERAGE(S8:V8) -> 3.5 | AR8: =AVERAGE(W8,X8,Z8,AB8) -> 3.75 | AS8: =AVERAGE(AC8:AF8) -> 3.5 | AT8: =AVERAGE(Y8,AA8,AG8:AM8) -> 2.25 | AU8: =(AO8+AP8+AQ8+AR8+AS8+(6-AT8))/6 -> 3.85 | AV8: Moyenne | AW8: Faible | AX8: 3 | AY8: D4 4→5
A9: 284 | B9: Ined | C9: Discriminations ethnoraciales et trajectoires d'entrée dans la vie active des descendants d'immigrés | D9: Sociologie Quantitative | E9: 1 | F9: 1 | G9: 1 | H9: 1 | I9: 1 | J9: 1 | K9: 2 | L9: 3 | N9: 3 | O9: 2 | P9: 3 | Q9: 3 | R9: 3 | S9: 2 | T9: 3 | U9: 3 | V9: 3 | W9: 3 | X9: 5 | Y9: 2 | Z9: 2 | AA9: 3 | AB9: 3 | AC9: 2 | AD9: 4 | AE9: 3 | AF9: 4 | AG9: 3 | AH9: 3 | AI9: 4 | AK9: 2 | AL9: 3 | AM9: 1 | AN9: 1 | AO9: =MAX(E9:K9) -> 2 | AP9: =AVERAGE(N9:R9) -> 2.8 | AQ9: =AVERAGE(S9:V9) -> 2.75 | AR9: =AVERAGE(W9,X9,Z9,AB9) -> 3.25 | AS9: =AVERAGE(AC9:AF9) -> 3.25 | AT9: =AVERAGE(Y9,AA9,AG9:AM9) -> 2.625 | AU9: =(AO9+AP9+AQ9+AR9+AS9+(6-AT9))/6 -> 2.9041667 | AV9: Haute | AW9: Faible | AX9: non noté
A10: 285 | B10: SCOR | C10: Life and health insurance pricing with geographical data | D10: Actuariat | E10: 3 | F10: 1 | G10: 5 | H10: 1 | I10: 2 | J10: 4 | K10: 1 | L10: 5 | N10: 4 | O10: 5 | P10: 3 | Q10: 5 | R10: 3 | S10: 5 | T10: 4 | U10: 5 | V10: 4 | W10: 3 | X10: 4 | Y10: 4 | Z10: 5 | AA10: 2 | AB10: 3 | AC10: 3 | AD10: 4 | AE10: 2 | AF10: 3 | AG10: 3 | AH10: 3 | AI10: 4 | AK10: 3 | AL10: 2 | AM10: 4 | AN10: 5 | AO10: =MAX(E10:K10) -> 5 | AP10: =AVERAGE(N10:R10) -> 4 | AQ10: =AVERAGE(S10:V10) -> 4.5 | AR10: =AVERAGE(W10,X10,Z10,AB10) -> 3.75 | AS10: =AVERAGE(AC10:AF10) -> 3 | AT10: =AVERAGE(Y10,AA10,AG10:AM10) -> 3.125 | AU10: =(AO10+AP10+AQ10+AR10+AS10+(6-AT10))/6 -> 3.8541667 | AV10: Haute | AW10: Faible | AX10: 3
A11: 288 | B11: Société Générale | C11: L'incertitude des systèmes multi-agents | D11: Autre | E11: 1 | F11: 1 | G11: 1 | H11: 1 | I11: 2 | J11: 1 | K11: 1 | L11: 3 | N11: 5 | O11: 3 | P11: 3 | Q11: 3 | R11: 4 | S11: 3 | T11: 3 | U11: 4 | V11: 3 | W11: 2 | X11: 4 | Y11: 3 | Z11: 1 | AA11: 5 | AB11: 3 | AC11: 3 | AD11: 5 | AE11: 4 | AF11: 3 | AG11: 5 | AH11: 5 | AI11: 3 | AK11: 5 | AL11: 3 | AM11: 2 | AN11: 3 | AO11: =MAX(E11:K11) -> 2 | AP11: =AVERAGE(N11:R11) -> 3.6 | AQ11: =AVERAGE(S11:V11) -> 3.25 | AR11: =AVERAGE(W11,X11,Z11,AB11) -> 2.5 | AS11: =AVERAGE(AC11:AF11) -> 3.75 | AT11: =AVERAGE(Y11,AA11,AG11:AM11) -> 3.875 | AU11: =(AO11+AP11+AQ11+AR11+AS11+(6-AT11))/6 -> 2.8708333 | AV11: Haute | AW11: Faible | AX11: 2
A12: 289 | B12: DG Trésor | C12: Analyse sectorielle des fluctuations du prix du pétrole | D12: Macroeconomie | E12: 1 | F12: 1 | G12: 1 | H12: 2 | I12: 2 | J12: 1 | K12: 3 | L12: 3 | N12: 4 | O12: 4 | P12: 3 | Q12: 4 | R12: 3 | S12: 3 | T12: 4 | U12: 3 | V12: 4 | W12: 3 | X12: 3 | Y12: 1 | Z12: 5 | AA12: 2 | AB12: 3 | AC12: 3 | AD12: 3 | AE12: 3 | AF12: 3 | AG12: 2 | AH12: 2 | AI12: 3 | AK12: 1 | AL12: 3 | AM12: 1 | AN12: 3 | AO12: =MAX(E12:K12) -> 3 | AP12: =AVERAGE(N12:R12) -> 3.6 | AQ12: =AVERAGE(S12:V12) -> 3.5 | AR12: =AVERAGE(W12,X12,Z12,AB12) -> 3.5 | AS12: =AVERAGE(AC12:AF12) -> 3 | AT12: =AVERAGE(Y12,AA12,AG12:AM12) -> 1.875 | AU12: =(AO12+AP12+AQ12+AR12+AS12+(6-AT12))/6 -> 3.4541667 | AV12: Haute | AW12: Faible | AX12: non noté
A13: 290 | B13: DG Trésor | C13: L'impact économique du vieillissement | D13: Macroeconomie | E13: 1 | F13: 1 | G13: 2 | H13: 1 | I13: 2 | J13: 1 | K13: 3 | L13: 3 | N13: 4 | O13: 4 | P13: 3 | Q13: 5 | R13: 3 | S13: 3 | T13: 4 | U13: 3 | V13: 3 | W13: 3 | X13: 3 | Y13: 1 | Z13: 4 | AA13: 3 | AB13: 3 | AC13: 3 | AD13: 2 | AE13: 3 | AF13: 3 | AG13: 2 | AH13: 3 | AI13: 2 | AK13: 2 | AL13: 2 | AM13: 1 | AN13: 3 | AO13: =MAX(E13:K13) -> 3 | AP13: =AVERAGE(N13:R13) -> 3.8 | AQ13: =AVERAGE(S13:V13) -> 3.25 | AR13: =AVERAGE(W13,X13,Z13,AB13) -> 3.25 | AS13: =AVERAGE(AC13:AF13) -> 2.75 | AT13: =AVERAGE(Y13,AA13,AG13:AM13) -> 2 | AU13: =(AO13+AP13+AQ13+AR13+AS13+(6-AT13))/6 -> 3.3416667 | AV13: Moyenne | AW13: Faible | AX13: non noté
A14: 291 | B14: RTE | C14: Analyse longitudinale de la base OPERAT - Comment les consommations énergétiques des établissements tertiaire… | D14: Environnement Energie et Mobilité | E14: 1 | F14: 1 | G14: 1 | H14: 1 | I14: 1 | J14: 1 | K14: 2 | L14: 3 | N14: 4 | O14: 2 | P14: 3 | Q14: 2 | R14: 2 | S14: 3 | T14: 2 | U14: 2 | V14: 3 | W14: 3 | X14: 3 | Y14: 2 | Z14: 4 | AA14: 4 | AB14: 3 | AC14: 2 | AD14: 2 | AE14: 3 | AF14: 3 | AG14: 3 | AH14: 2 | AI14: 3 | AK14: 2 | AL14: 3 | AM14: 2 | AN14: 2 | AO14: =MAX(E14:K14) -> 2 | AP14: =AVERAGE(N14:R14) -> 2.6 | AQ14: =AVERAGE(S14:V14) -> 2.5 | AR14: =AVERAGE(W14,X14,Z14,AB14) -> 3.25 | AS14: =AVERAGE(AC14:AF14) -> 2.5 | AT14: =AVERAGE(Y14,AA14,AG14:AM14) -> 2.625 | AU14: =(AO14+AP14+AQ14+AR14+AS14+(6-AT14))/6 -> 2.7041667 | AV14: Moyenne | AW14: Faible | AX14: non noté
A15: 292 | B15: CREST ENSAE | C15: Semantic Credit Risk Pricing with Large Language Models | D15: Actuariat | E15: 2 | F15: 1 | G15: 1 | H15: 2 | I15: 2 | J15: 2 | K15: 1 | L15: 4 | N15: 4 | O15: 3 | P15: 2 | Q15: 4 | R15: 4 | S15: 2 | T15: 3 | U15: 4 | V15: 4 | W15: 3 | X15: 4 | Y15: 1 | Z15: 3 | AA15: 3 | AB15: 3 | AC15: 2 | AD15: 5 | AE15: 5 | AF15: 3 | AG15: 3 | AH15: 4 | AI15: 1 | AK15: 4 | AL15: 2 | AM15: 1 | AN15: 4 | AO15: =MAX(E15:K15) -> 2 | AP15: =AVERAGE(N15:R15) -> 3.4 | AQ15: =AVERAGE(S15:V15) -> 3.25 | AR15: =AVERAGE(W15,X15,Z15,AB15) -> 3.25 | AS15: =AVERAGE(AC15:AF15) -> 3.75 | AT15: =AVERAGE(Y15,AA15,AG15:AM15) -> 2.375 | AU15: =(AO15+AP15+AQ15+AR15+AS15+(6-AT15))/6 -> 3.2125 | AV15: Haute | AW15: Faible | AX15: non noté
A16: 293 | B16: QuantCube Technology | C16: Nowcasting hiérarchique de la consommation des ménages en Espagne | D16: Macroeconomie | E16: 1 | F16: 1 | G16: 1 | H16: 2 | I16: 2 | J16: 1 | K16: 3 | L16: 4 | N16: 2 | O16: 3 | P16: 3 | Q16: 4 | R16: 4 | S16: 2 | T16: 2 | U16: 3 | V16: 4 | W16: 3 | X16: 5 | Y16: 3 | Z16: 3 | AA16: 4 | AB16: 3 | AC16: 4 | AD16: 5 | AE16: 4 | AF16: 5 | AG16: 4 | AH16: 4 | AI16: 4 | AK16: 3 | AL16: 2 | AM16: 3 | AN16: 2 | AO16: =MAX(E16:K16) -> 3 | AP16: =AVERAGE(N16:R16) -> 3.2 | AQ16: =AVERAGE(S16:V16) -> 2.75 | AR16: =AVERAGE(W16,X16,Z16,AB16) -> 3.5 | AS16: =AVERAGE(AC16:AF16) -> 4.5 | AT16: =AVERAGE(Y16,AA16,AG16:AM16) -> 3.375 | AU16: =(AO16+AP16+AQ16+AR16+AS16+(6-AT16))/6 -> 3.2625 | AV16: Haute | AW16: Faible | AX16: non noté
A17: 294 | B17: Ined | C17: Evolution des thématiques de recherche en démographie : le cas des publications de l'Ined | D17: Sociologie Quantitative | E17: 1 | F17: 1 | G17: 1 | H17: 1 | I17: 1 | J17: 1 | K17: 2 | L17: 3 | N17: 3 | O17: 2 | P17: 3 | Q17: 3 | R17: 3 | S17: 2 | T17: 3 | U17: 3 | V17: 3 | W17: 3 | X17: 3 | Y17: 2 | Z17: 3 | AA17: 3 | AB17: 3 | AC17: 2 | AD17: 3 | AE17: 3 | AF17: 4 | AG17: 3 | AH17: 3 | AI17: 4 | AK17: 2 | AL17: 3 | AM17: 1 | AN17: 1 | AO17: =MAX(E17:K17) -> 2 | AP17: =AVERAGE(N17:R17) -> 2.8 | AQ17: =AVERAGE(S17:V17) -> 2.75 | AR17: =AVERAGE(W17,X17,Z17,AB17) -> 3 | AS17: =AVERAGE(AC17:AF17) -> 3 | AT17: =AVERAGE(Y17,AA17,AG17:AM17) -> 2.625 | AU17: =(AO17+AP17+AQ17+AR17+AS17+(6-AT17))/6 -> 2.8208333 | AV17: Haute | AW17: Faible | AX17: non noté
A18: 295 | B18: QuantCube Technology | C18: Nowcasting des Nonfarm Payrolls américains à partir de données alternatives haute fréquence | D18: Macroeconomie | E18: 1 | F18: 1 | G18: 1 | H18: 3 | I18: 2 | J18: 1 | K18: 2 | L18: 4 | N18: 2 | O18: 3 | P18: 3 | Q18: 4 | R18: 3 | S18: 2 | T18: 2 | U18: 3 | V18: 5 | W18: 3 | X18: 5 | Y18: 3 | Z18: 3 | AA18: 3 | AB18: 3 | AC18: 4 | AD18: 4 | AE18: 4 | AF18: 3 | AG18: 4 | AH18: 4 | AI18: 4 | AK18: 3 | AL18: 2 | AM18: 3 | AN18: 3 | AO18: =MAX(E18:K18) -> 3 | AP18: =AVERAGE(N18:R18) -> 3 | AQ18: =AVERAGE(S18:V18) -> 3 | AR18: =AVERAGE(W18,X18,Z18,AB18) -> 3.5 | AS18: =AVERAGE(AC18:AF18) -> 3.75 | AT18: =AVERAGE(Y18,AA18,AG18:AM18) -> 3.25 | AU18: =(AO18+AP18+AQ18+AR18+AS18+(6-AT18))/6 -> 3.1666667 | AV18: Haute | AW18: Faible | AX18: non noté
A19: 296 | B19: Partners Group | C19: Mandates representation and optimization via cross trades | D19: Finance | E19: 1 | F19: 1 | G19: 1 | H19: 3 | I19: 2 | J19: 1 | K19: 1 | L19: 3 | N19: 4 | O19: 3 | P19: 3 | Q19: 2 | R19: 2 | S19: 4 | T19: 3 | U19: 5 | V19: 3 | W19: 2 | X19: 1 | Y19: 5 | Z19: 3 | AA19: 4 | AB19: 3 | AC19: 3 | AD19: 3 | AE19: 2 | AF19: 4 | AG19: 4 | AH19: 4 | AI19: 4 | AK19: 4 | AL19: 3 | AM19: 4 | AN19: 2 | AO19: =MAX(E19:K19) -> 3 | AP19: =AVERAGE(N19:R19) -> 2.8 | AQ19: =AVERAGE(S19:V19) -> 3.75 | AR19: =AVERAGE(W19,X19,Z19,AB19) -> 2.25 | AS19: =AVERAGE(AC19:AF19) -> 3 | AT19: =AVERAGE(Y19,AA19,AG19:AM19) -> 4 | AU19: =(AO19+AP19+AQ19+AR19+AS19+(6-AT19))/6 -> 2.8 | AV19: Moyenne | AW19: Faible | AX19: 2 | AY19: D2 2→1, D3 4→5
A20: 297 | B20: ENGIE | C20: Generate plausible gas consumption scenarios for the upcoming year under unknown weather conditions. | D20: Predictions | E20: 2 | F20: 4 | G20: 1 | H20: 2 | I20: 3 | J20: 1 | K20: 1 | L20: 4 | N20: 5 | O20: 2 | P20: 3 | Q20: 3 | R20: 3 | S20: 3 | T20: 2 | U20: 5 | V20: 4 | W20: 3 | X20: 3 | Y20: 3 | Z20: 3 | AA20: 3 | AB20: 3 | AC20: 4 | AD20: 4 | AE20: 3 | AF20: 4 | AG20: 3 | AH20: 3 | AI20: 3 | AK20: 3 | AL20: 2 | AM20: 3 | AN20: 2 | AO20: =MAX(E20:K20) -> 4 | AP20: =AVERAGE(N20:R20) -> 3.2 | AQ20: =AVERAGE(S20:V20) -> 3.5 | AR20: =AVERAGE(W20,X20,Z20,AB20) -> 3 | AS20: =AVERAGE(AC20:AF20) -> 3.75 | AT20: =AVERAGE(Y20,AA20,AG20:AM20) -> 2.875 | AU20: =(AO20+AP20+AQ20+AR20+AS20+(6-AT20))/6 -> 3.4291667 | AV20: Moyenne | AW20: Faible | AX20: non noté
A21: 298 | B21: ENGIE | C21: Belgium's Hourly Gas Consumption Model: Accuracy and Relevance | D21: Predictions | E21: 1 | F21: 1 | G21: 1 | H21: 1 | I21: 2 | J21: 1 | K21: 1 | L21: 3 | N21: 5 | O21: 2 | P21: 3 | Q21: 3 | R21: 2 | S21: 3 | T21: 2 | U21: 5 | V21: 3 | W21: 3 | X21: 3 | Y21: 3 | Z21: 4 | AA21: 3 | AB21: 3 | AC21: 2 | AD21: 2 | AE21: 2 | AF21: 2 | AG21: 3 | AH21: 2 | AI21: 2 | AK21: 3 | AL21: 3 | AM21: 4 | AN21: 2 | AO21: =MAX(E21:K21) -> 2 | AP21: =AVERAGE(N21:R21) -> 3 | AQ21: =AVERAGE(S21:V21) -> 3.25 | AR21: =AVERAGE(W21,X21,Z21,AB21) -> 3.25 | AS21: =AVERAGE(AC21:AF21) -> 2 | AT21: =AVERAGE(Y21,AA21,AG21:AM21) -> 2.875 | AU21: =(AO21+AP21+AQ21+AR21+AS21+(6-AT21))/6 -> 2.7708333 | AV21: Moyenne | AW21: Faible | AX21: non noté
A22: 299 | B22: Ekimetrics | C22: Prévision de la demande pour un éditeur de presse | D22: Predictions | E22: 1 | F22: 1 | G22: 1 | H22: 1 | I22: 3 | J22: 1 | K22: 1 | L22: 3 | N22: 3 | O22: 3 | P22: 3 | Q22: 4 | R22: 2 | S22: 4 | T22: 3 | U22: 4 | V22: 4 | W22: 3 | X22: 2 | Y22: 4 | Z22: 3 | AA22: 3 | AB22: 3 | AC22: 2 | AD22: 2 | AE22: 2 | AF22: 2 | AG22: 3 | AH22: 2 | AI22: 4 | AK22: 3 | AL22: 3 | AM22: 4 | AN22: 2 | AO22: =MAX(E22:K22) -> 3 | AP22: =AVERAGE(N22:R22) -> 3 | AQ22: =AVERAGE(S22:V22) -> 3.75 | AR22: =AVERAGE(W22,X22,Z22,AB22) -> 2.75 | AS22: =AVERAGE(AC22:AF22) -> 2 | AT22: =AVERAGE(Y22,AA22,AG22:AM22) -> 3.25 | AU22: =(AO22+AP22+AQ22+AR22+AS22+(6-AT22))/6 -> 2.875 | AV22: Moyenne | AW22: Faible | AX22: non noté
A23: 300 | B23: European University Institute | C23: The Effects of Geopolitical Risk on Innovation: Evidence from International Patent Data | D23: Macroeconomie | E23: 1 | F23: 1 | G23: 1 | H23: 2 | I23: 2 | J23: 1 | K23: 3 | L23: 4 | N23: 4 | O23: 3 | P23: 3 | Q23: 4 | R23: 4 | S23: 2 | T23: 3 | U23: 5 | V23: 4 | W23: 3 | X23: 3 | Y23: 2 | Z23: 4 | AA23: 3 | AB23: 3 | AC23: 3 | AD23: 4 | AE23: 4 | AF23: 4 | AG23: 4 | AH23: 3 | AI23: 4 | AK23: 3 | AL23: 2 | AM23: 1 | AN23: 2 | AO23: =MAX(E23:K23) -> 3 | AP23: =AVERAGE(N23:R23) -> 3.6 | AQ23: =AVERAGE(S23:V23) -> 3.5 | AR23: =AVERAGE(W23,X23,Z23,AB23) -> 3.25 | AS23: =AVERAGE(AC23:AF23) -> 3.75 | AT23: =AVERAGE(Y23,AA23,AG23:AM23) -> 2.75 | AU23: =(AO23+AP23+AQ23+AR23+AS23+(6-AT23))/6 -> 3.3916667 | AV23: Moyenne | AW23: Faible | AX23: non noté
A24: 301 | B24: Withings SAS | C24: Souscription et résiliation d'un abonnement de santé connectée : détecter les signaux d'usage précurseurs et… | D24: Marketing Quantitatif | E24: 1 | F24: 1 | G24: 2 | H24: 2 | I24: 4 | J24: 1 | K24: 1 | L24: 5 | N24: 4 | O24: 2 | P24: 3 | Q24: 3 | R24: 3 | S24: 2 | T24: 2 | U24: 3 | V24: 5 | W24: 3 | X24: 5 | Y24: 2 | Z24: 4 | AA24: 3 | AB24: 3 | AC24: 4 | AD24: 5 | AE24: 3 | AF24: 3 | AG24: 4 | AH24: 4 | AI24: 4 | AK24: 3 | AL24: 2 | AM24: 4 | AN24: 3 | AO24: =MAX(E24:K24) -> 4 | AP24: =AVERAGE(N24:R24) -> 3 | AQ24: =AVERAGE(S24:V24) -> 3 | AR24: =AVERAGE(W24,X24,Z24,AB24) -> 3.75 | AS24: =AVERAGE(AC24:AF24) -> 3.75 | AT24: =AVERAGE(Y24,AA24,AG24:AM24) -> 3.25 | AU24: =(AO24+AP24+AQ24+AR24+AS24+(6-AT24))/6 -> 3.375 | AV24: Haute | AW24: Faible | AX24: non noté
A25: 302 | B25: WOAH | C25: Animal Health as Market and Trade Intelligence | D25: Microéconomie Appliquée | E25: 1 | F25: 3 | G25: 1 | H25: 3 | I25: 2 | J25: 1 | K25: 5 | L25: 5 | N25: 3 | O25: 3 | P25: 4 | Q25: 3 | R25: 3 | S25: 3 | T25: 3 | U25: 5 | V25: 4 | W25: 3 | X25: 2 | Y25: 2 | Z25: 4 | AA25: 4 | AB25: 3 | AC25: 3 | AD25: 5 | AE25: 4 | AF25: 5 | AG25: 4 | AH25: 4 | AI25: 5 | AK25: 3 | AL25: 1 | AM25: 1 | AN25: 2 | AO25: =MAX(E25:K25) -> 5 | AP25: =AVERAGE(N25:R25) -> 3.2 | AQ25: =AVERAGE(S25:V25) -> 3.75 | AR25: =AVERAGE(W25,X25,Z25,AB25) -> 3 | AS25: =AVERAGE(AC25:AF25) -> 4.25 | AT25: =AVERAGE(Y25,AA25,AG25:AM25) -> 3 | AU25: =(AO25+AP25+AQ25+AR25+AS25+(6-AT25))/6 -> 3.7 | AV25: Moyenne | AW25: Moyenne | AX25: non noté
A26: 303 | B26: WOAH | C26: Embeddings for Epidemic Intelligence | D26: NLP | E26: 1 | F26: 2 | G26: 1 | H26: 1 | I26: 2 | J26: 1 | K26: 4 | L26: 5 | N26: 3 | O26: 3 | P26: 4 | Q26: 4 | R26: 4 | S26: 3 | T26: 3 | U26: 5 | V26: 5 | W26: 3 | X26: 5 | Y26: 3 | Z26: 2 | AA26: 4 | AB26: 3 | AC26: 4 | AD26: 5 | AE26: 4 | AF26: 4 | AG26: 5 | AH26: 4 | AI26: 5 | AK26: 4 | AL26: 2 | AM26: 1 | AN26: 2 | AO26: =MAX(E26:K26) -> 4 | AP26: =AVERAGE(N26:R26) -> 3.6 | AQ26: =AVERAGE(S26:V26) -> 4 | AR26: =AVERAGE(W26,X26,Z26,AB26) -> 3.25 | AS26: =AVERAGE(AC26:AF26) -> 4.25 | AT26: =AVERAGE(Y26,AA26,AG26:AM26) -> 3.5 | AU26: =(AO26+AP26+AQ26+AR26+AS26+(6-AT26))/6 -> 3.6 | AV26: Haute | AW26: Moyenne | AX26: non noté
A27: 304 | B27: GazTransport et Technigaz | C27: Identification des anomalies de trajectoires de méthaniers pour l'obtention de statistiques agrégées sur les… | D27: Environnement Energie et Mobilité | E27: 1 | F27: 1 | G27: 1 | H27: 1 | I27: 2 | J27: 1 | K27: 1 | L27: 4 | N27: 3 | O27: 1 | P27: 3 | Q27: 2 | R27: 2 | S27: 2 | T27: 2 | U27: 3 | V27: 4 | W27: 3 | X27: 4 | Y27: 3 | Z27: 3 | AA27: 3 | AB27: 3 | AC27: 2 | AD27: 3 | AE27: 3 | AF27: 3 | AG27: 4 | AH27: 3 | AI27: 3 | AK27: 3 | AL27: 2 | AM27: 3 | AN27: 2 | AO27: =MAX(E27:K27) -> 2 | AP27: =AVERAGE(N27:R27) -> 2.2 | AQ27: =AVERAGE(S27:V27) -> 2.75 | AR27: =AVERAGE(W27,X27,Z27,AB27) -> 3.25 | AS27: =AVERAGE(AC27:AF27) -> 2.75 | AT27: =AVERAGE(Y27,AA27,AG27:AM27) -> 3 | AU27: =(AO27+AP27+AQ27+AR27+AS27+(6-AT27))/6 -> 2.6583333 | AV27: Haute | AW27: Faible | AX27: non noté
A28: 305 | B28: CREST | C28: Disaster Risk Reduction and Climate Change Adaptation in European Metropolises | D28: Environnement Energie et Mobilité | E28: 1 | F28: 4 | G28: 1 | H28: 1 | I28: 2 | J28: 1 | K28: 4 | L28: 4 | N28: 4 | O28: 3 | P28: 5 | Q28: 4 | R28: 5 | S28: 2 | T28: 3 | U28: 5 | V28: 3 | W28: 3 | X28: 2 | Y28: 3 | Z28: 2 | AA28: 4 | AB28: 4 | AC28: 3 | AD28: 5 | AE28: 4 | AF28: 5 | AG28: 4 | AH28: 4 | AI28: 4 | AK28: 3 | AL28: 2 | AM28: 2 | AN28: 2 | AO28: =MAX(E28:K28) -> 4 | AP28: =AVERAGE(N28:R28) -> 4.2 | AQ28: =AVERAGE(S28:V28) -> 3.25 | AR28: =AVERAGE(W28,X28,Z28,AB28) -> 2.75 | AS28: =AVERAGE(AC28:AF28) -> 4.25 | AT28: =AVERAGE(Y28,AA28,AG28:AM28) -> 3.25 | AU28: =(AO28+AP28+AQ28+AR28+AS28+(6-AT28))/6 -> 3.5333333 | AV28: Moyenne | AW28: Moyenne | AX28: non noté
A29: 306 | B29: CREST UMR 9194 | C29: Résultats des élections municipales à Paris et caractéristiques des quartiers | D29: Microéconomie Appliquée | E29: 1 | F29: 1 | G29: 1 | H29: 1 | I29: 1 | J29: 1 | K29: 2 | L29: 3 | N29: 4 | O29: 3 | P29: 4 | Q29: 4 | R29: 3 | S29: 2 | T29: 3 | U29: 4 | V29: 3 | W29: 3 | X29: 3 | Y29: 1 | Z29: 4 | AA29: 3 | AB29: 4 | AC29: 2 | AD29: 3 | AE29: 4 | AF29: 4 | AG29: 3 | AH29: 2 | AI29: 3 | AK29: 2 | AL29: 3 | AM29: 1 | AN29: 3 | AO29: =MAX(E29:K29) -> 2 | AP29: =AVERAGE(N29:R29) -> 3.6 | AQ29: =AVERAGE(S29:V29) -> 3 | AR29: =AVERAGE(W29,X29,Z29,AB29) -> 3.5 | AS29: =AVERAGE(AC29:AF29) -> 3.25 | AT29: =AVERAGE(Y29,AA29,AG29:AM29) -> 2.25 | AU29: =(AO29+AP29+AQ29+AR29+AS29+(6-AT29))/6 -> 3.1833333 | AV29: Haute | AW29: Moyenne | AX29: non noté
A30: 307 | B30: CREST UMR 9194 | C30: Prix des forêts, composition du couvert forestier et caractéristiques locales | D30: Microéconomie Appliquée | E30: 1 | F30: 2 | G30: 1 | H30: 1 | I30: 2 | J30: 1 | K30: 2 | L30: 4 | N30: 4 | O30: 3 | P30: 4 | Q30: 3 | R30: 4 | S30: 2 | T30: 3 | U30: 4 | V30: 4 | W30: 3 | X30: 4 | Y30: 2 | Z30: 4 | AA30: 2 | AB30: 4 | AC30: 3 | AD30: 3 | AE30: 4 | AF30: 4 | AG30: 3 | AH30: 2 | AI30: 4 | AK30: 2 | AL30: 3 | AM30: 1 | AN30: 2 | AO30: =MAX(E30:K30) -> 2 | AP30: =AVERAGE(N30:R30) -> 3.6 | AQ30: =AVERAGE(S30:V30) -> 3.25 | AR30: =AVERAGE(W30,X30,Z30,AB30) -> 3.75 | AS30: =AVERAGE(AC30:AF30) -> 3.5 | AT30: =AVERAGE(Y30,AA30,AG30:AM30) -> 2.375 | AU30: =(AO30+AP30+AQ30+AR30+AS30+(6-AT30))/6 -> 3.2875 | AV30: Haute | AW30: Moyenne | AX30: non noté
A31: 308 | B31: Ekimetrics | C31: Sensibilité au choix des lois a priori dans les modèles bayésiens hiérarchiques : effets sur l'estimation et… | D31: Marketing Quantitatif | E31: 1 | F31: 1 | G31: 1 | H31: 2 | I31: 3 | J31: 1 | K31: 1 | L31: 5 | N31: 3 | O31: 3 | P31: 3 | Q31: 2 | R31: 5 | S31: 4 | T31: 3 | U31: 4 | V31: 3 | W31: 3 | X31: 5 | Y31: 1 | Z31: 2 | AA31: 5 | AB31: 3 | AC31: 5 | AD31: 5 | AE31: 5 | AF31: 5 | AG31: 5 | AH31: 5 | AI31: 1 | AK31: 3 | AL31: 2 | AM31: 2 | AN31: 1 | AO31: =MAX(E31:K31) -> 3 | AP31: =AVERAGE(N31:R31) -> 3.2 | AQ31: =AVERAGE(S31:V31) -> 3.5 | AR31: =AVERAGE(W31,X31,Z31,AB31) -> 3.25 | AS31: =AVERAGE(AC31:AF31) -> 5 | AT31: =AVERAGE(Y31,AA31,AG31:AM31) -> 3 | AU31: =(AO31+AP31+AQ31+AR31+AS31+(6-AT31))/6 -> 3.4916667 | AV31: Haute | AW31: Faible | AX31: non noté
